<?xml version="1.0" ?>
<!-- =================================================================================== -->
<!-- |    This document was autogenerated by xacro from /home/kuwagata/catkin_ws/src/six_dof_cam/six_dof_cam_description/urdf/six_dof_cam.xacro | -->
<!-- |    EDITING THIS FILE BY HAND IS NOT RECOMMENDED                                 | -->
<!-- =================================================================================== -->
<robot name="six_dof_cam" xmlns:xacro="http://ros.org/wiki/xacro">
  <!-- =============== Link & Joint =============== -->
  <link name="world"/>
  <joint name="x_linear_actuator_joint" type="prismatic">
    <origin rpy="0 0 0" xyz="0 0 1"/>
    <axis xyz="1 0 0"/>
    <parent link="world"/>
    <child link="x_linear_actuator_link"/>
    <limit effort="0.5" lower="-1" upper="1" velocity="5.0"/>
  </joint>
  <link name="x_linear_actuator_link">
    <inertial>
      <origin xyz="0 0 0"/>
      <mass value="0.0"/>
      <inertia ixx="0.0" ixy="0.0" ixz="0.0" iyy="0.0" iyz="0.0" izz="0.0"/>
    </inertial>
  </link>
  <joint name="y_linear_actuator_joint" type="prismatic">
    <origin rpy="0 0 0" xyz="0 0 0"/>
    <axis xyz="0 1 0"/>
    <parent link="x_linear_actuator_link"/>
    <child link="y_linear_actuator_link"/>
    <limit effort="0.5" lower="-1" upper="1" velocity="5.0"/>
  </joint>
  <link name="y_linear_actuator_link">
    <inertial>
      <origin xyz="0 0 0"/>
      <mass value="0.0"/>
      <inertia ixx="0.0" ixy="0.0" ixz="0.0" iyy="0.0" iyz="0.0" izz="0.0"/>
    </inertial>
  </link>
  <joint name="z_linear_actuator_joint" type="prismatic">
    <origin rpy="0 0 0" xyz="0 0 0"/>
    <axis xyz="0 0 1"/>
    <parent link="y_linear_actuator_link"/>
    <child link="z_linear_actuator_link"/>
    <limit effort="0.5" lower="-1" upper="1" velocity="5.0"/>
  </joint>
  <link name="z_linear_actuator_link">
    <inertial>
      <origin xyz="0 0 0"/>
      <mass value="0.0"/>
      <inertia ixx="0.0" ixy="0.0" ixz="0.0" iyy="0.0" iyz="0.0" izz="0.0"/>
    </inertial>
  </link>
  <joint name="x_rotary_actuator_joint" type="revolute">
    <origin rpy="0 0 0" xyz="0 0 0"/>
    <axis xyz="1 0 0"/>
    <parent link="z_linear_actuator_link"/>
    <child link="x_rotary_actuator_link"/>
    <limit effort="0.5" lower="-3.14" upper="3.14" velocity="5.0"/>
  </joint>
  <link name="x_rotary_actuator_link">
    <inertial>
      <origin xyz="0 0 0"/>
      <mass value="0.0"/>
      <inertia ixx="0.0" ixy="0.0" ixz="0.0" iyy="0.0" iyz="0.0" izz="0.0"/>
    </inertial>
  </link>
  <joint name="y_rotary_actuator_joint" type="revolute">
    <origin rpy="0 0 0" xyz="0 0 0"/>
    <axis xyz="0 1 0"/>
    <parent link="x_rotary_actuator_link"/>
    <child link="y_rotary_actuator_link"/>
    <limit effort="0.5" lower="-3.14" upper="3.14" velocity="5.0"/>
  </joint>
  <link name="y_rotary_actuator_link">
    <inertial>
      <origin xyz="0 0 0"/>
      <mass value="0.0"/>
      <inertia ixx="0.0" ixy="0.0" ixz="0.0" iyy="0.0" iyz="0.0" izz="0.0"/>
    </inertial>
  </link>
  <joint name="z_rotary_actuator_joint" type="revolute">
    <origin rpy="0 0 0" xyz="0 0 0"/>
    <axis xyz="0 0 1"/>
    <parent link="y_rotary_actuator_link"/>
    <child link="z_rotary_actuator_link"/>
    <limit effort="0.5" lower="-3.14" upper="3.14" velocity="5.0"/>
  </joint>
  <link name="z_rotary_actuator_link">
    <inertial>
      <origin xyz="0 0 0"/>
      <mass value="0.0"/>
      <inertia ixx="0.0" ixy="0.0" ixz="0.0" iyy="0.0" iyz="0.0" izz="0.0"/>
    </inertial>
  </link>
  <joint name="camera_joint" type="fixed">
    <origin rpy="0 0 0" xyz="0 0 0"/>
    <parent link="z_rotary_actuator_link"/>
    <child link="camera_link"/>
  </joint>
  <link name="camera_link">
    <visual>
      <geometry>
        <box size="0.1 0.1 0.1"/>
      </geometry>
    </visual>
    <collision>
      <geometry>
        <box size="0.1 0.1 0.1"/>
      </geometry>
    </collision>
    <inertial>
      <origin rpy="0 0 0" xyz="0 0 0"/>
      <mass value="1.0"/>
      <inertia ixx="1.0" ixy="0.0" ixz="0.0" iyy="1.0" iyz="0.0" izz="1.0"/>
    </inertial>
  </link>
  <transmission name="x_linear_actuator_trans">
    <type>transmission_interface/SimpleTransmission</type>
    <joint name="x_linear_actuator_joint">
      <hardwareInterface>PositionJointInterface</hardwareInterface>
    </joint>
    <actuator name="x_linear_actuator_motor">
      <hardwareInterface>PositionJointInterface</hardwareInterface>
    </actuator>
  </transmission>
  <transmission name="y_linear_actuator_trans">
    <type>transmission_interface/SimpleTransmission</type>
    <joint name="y_linear_actuator_joint">
      <hardwareInterface>PositionJointInterface</hardwareInterface>
    </joint>
    <actuator name="y_linear_actuator_motor">
      <hardwareInterface>PositionJointInterface</hardwareInterface>
    </actuator>
  </transmission>
  <transmission name="z_linear_actuator_trans">
    <type>transmission_interface/SimpleTransmission</type>
    <joint name="z_linear_actuator_joint">
      <hardwareInterface>PositionJointInterface</hardwareInterface>
    </joint>
    <actuator name="z_linear_actuator_motor">
      <hardwareInterface>PositionJointInterface</hardwareInterface>
    </actuator>
  </transmission>
  <transmission name="x_rotary_actuator_trans">
    <type>transmission_interface/SimpleTransmission</type>
    <joint name="x_rotary_actuator_joint">
      <hardwareInterface>PositionJointInterface</hardwareInterface>
    </joint>
    <actuator name="x_rotary_actuator_motor">
      <hardwareInterface>PositionJointInterface</hardwareInterface>
    </actuator>
  </transmission>
  <transmission name="y_rotary_actuator_trans">
    <type>transmission_interface/SimpleTransmission</type>
    <joint name="y_rotary_actuator_joint">
      <hardwareInterface>PositionJointInterface</hardwareInterface>
    </joint>
    <actuator name="y_rotary_actuator_motor">
      <hardwareInterface>PositionJointInterface</hardwareInterface>
    </actuator>
  </transmission>
  <transmission name="z_rotary_actuator_trans">
    <type>transmission_interface/SimpleTransmission</type>
    <joint name="z_rotary_actuator_joint">
      <hardwareInterface>PositionJointInterface</hardwareInterface>
    </joint>
    <actuator name="z_rotary_actuator_motor">
      <hardwareInterface>PositionJointInterface</hardwareInterface>
    </actuator>
  </transmission>
  <!-- =============== Gazebo =============== -->
  <gazebo>
    <plugin filename="libgazebo_ros_control.so" name="gazebo_ros_control">
      <robotNamespace>six_dof_cam</robotNamespace>
    </plugin>
  </gazebo>
  <gazebo reference="camera_link">
    <!-- <selfCollide>true</selfCollide> -->
    <mu1>0.05</mu1>
    <mu2>0.05</mu2>
  </gazebo>
  <gazebo reference="x_rotary_actuator_link">
    <!-- <selfCollide>true</selfCollide> -->
    <mu1>0.05</mu1>
    <mu2>0.05</mu2>
  </gazebo>
  <gazebo reference="y_rotary_actuator_link">
    <!-- <selfCollide>true</selfCollide> -->
    <mu1>0.05</mu1>
    <mu2>0.05</mu2>
  </gazebo>
  <gazebo reference="z_rotary_actuator_link">
    <!-- <selfCollide>true</selfCollide> -->
    <mu1>0.05</mu1>
    <mu2>0.05</mu2>
  </gazebo>
  <gazebo reference="x_linear_actuator_link">
    <!-- <selfCollide>true</selfCollide> -->
    <mu1>0.05</mu1>
    <mu2>0.05</mu2>
  </gazebo>
  <gazebo reference="y_linear_actuator_link">
    <!-- <selfCollide>true</selfCollide> -->
    <mu1>0.05</mu1>
    <mu2>0.05</mu2>
  </gazebo>
  <gazebo reference="z_linear_actuator_link">
    <!-- <selfCollide>true</selfCollide> -->
    <mu1>0.05</mu1>
    <mu2>0.05</mu2>
  </gazebo>
</robot>

